Workbook
Name chart5: 'sales channel revenue'!$G$8
Name NativeTimeline_True_Date: #N/A
Name Slicer_Region: #N/A

Sheet Dashboard
T1: Count of Product ID | U1: Category
T2: Inventry Status | U2: Electronics | V2: Home Office | W2: Office Supplies
T3: REORDER | U3: 3 | V3: 1
T4: STABLE | U4: 1 | V4: 3 | W4: 3
T5: STOCK CRISIS | U5: 6 | V5: 6 | W5: 7

Sheet Clean_Sales_Data
A1: Transaction ID | B1: Date | C1: Product ID | D1: Quantity Sold | E1: Region | F1: Sales Channel | G1: True_Date | H1: REVENUE | I1: Month | J1: Month field
A2: TXN-1000 | B2: 2026-04-13 | C2: PROD-027 | D2: 14 | E2: Asia-Pacific | F2: Wholesale | G2: =IF(ISNUMBER(SEARCH("-", B2)), DATEVALUE(B2), DATE(RIGHT(B2,4), LEFT(B2, FIND("/", B2)-1), MID(B2, FIND("/", B2)+1, FIND("/", B2, FIND("/", B2)+1) - FIND("/", B2) - 1))) -> 46125 | H2: {=D2*_xlfn.XLOOKUP(C2,Clean_Inventry_Master!A:A,Clean_Inventry_Master!E:E,NOT FOUND,0)} -> 385 | I2: =DATE(YEAR(G2),MONTH(G2),1) -> 46113 | J2: =TEXT(I2,"mmm yyyy") -> Apr 2026
A3: TXN-1001 | B3: 2026-09-01 | C3: PROD-002 | D3: 10 | E3: Latin America | F3: In-Store | G3: =IF(ISNUMBER(SEARCH("-", B3)), DATEVALUE(B3), DATE(RIGHT(B3,4), LEFT(B3, FIND("/", B3)-1), MID(B3, FIND("/", B3)+1, FIND("/", B3, FIND("/", B3)+1) - FIND("/", B3) - 1))) -> 46266 | H3: {=D3*_xlfn.XLOOKUP(C3,Clean_Inventry_Master!A:A,Clean_Inventry_Master!E:E,NOT FOUND,0)} -> 1800 | I3: =DATE(YEAR(G3),MONTH(G3),1) -> 46266 | J3: =TEXT(I3,"mmm yyyy") -> Sep 2026
A4: TXN-1002 | B4: 07/21/2026 | C4: PROD-003 | D4: 5 | E4: Europe | F4: Wholesale | G4: =IF(ISNUMBER(SEARCH("-", B4)), DATEVALUE(B4), DATE(RIGHT(B4,4), LEFT(B4, FIND("/", B4)-1), MID(B4, FIND("/", B4)+1, FIND("/", B4, FIND("/", B4)+1) - FIND("/", B4) - 1))) -> 46224 | H4: {=D4*_xlfn.XLOOKUP(C4,Clean_Inventry_Master!A:A,Clean_Inventry_Master!E:E,NOT FOUND,0)} -> 2495 | I4: =DATE(YEAR(G4),MONTH(G4),1) -> 46204 | J4: =TEXT(I4,"mmm yyyy") -> Jul 2026
A5: TXN-1003 | B5: 02/10/2026 | C5: PROD-002 | D5: 13 | E5: Asia-Pacific | F5: Wholesale | G5: =IF(ISNUMBER(SEARCH("-", B5)), DATEVALUE(B5), DATE(RIGHT(B5,4), LEFT(B5, FIND("/", B5)-1), MID(B5, FIND("/", B5)+1, FIND("/", B5, FIND("/", B5)+1) - FIND("/", B5) - 1))) -> 46063 | H5: {=D5*_xlfn.XLOOKUP(C5,Clean_Inventry_Master!A:A,Clean_Inventry_Master!E:E,NOT FOUND,0)} -> 2340 | I5: =DATE(YEAR(G5),MONTH(G5),1) -> 46054 | J5: =TEXT(I5,"mmm yyyy") -> Feb 2026
A6: TXN-1004 | B6: 2026-08-19 | C6: PROD-020 | D6: 4 | E6: North America | F6: Online | G6: =IF(ISNUMBER(SEARCH("-", B6)), DATEVALUE(B6), DATE(RIGHT(B6,4), LEFT(B6, FIND("/", B6)-1), MID(B6, FIND("/", B6)+1, FIND("/", B6, FIND("/", B6)+1) - FIND("/", B6) - 1))) -> 46253 | H6: {=D6*_xlfn.XLOOKUP(C6,Clean_Inventry_Master!A:A,Clean_Inventry_Master!E:E,NOT FOUND,0)} -> 34 | I6: =DATE(YEAR(G6),MONTH(G6),1) -> 46235 | J6: =TEXT(I6,"mmm yyyy") -> Aug 2026
A7: TXN-1005 | B7: 2026-09-16 | C7: PROD-010 | D7: 1 | E7: North America | F7: Wholesale | G7: =IF(ISNUMBER(SEARCH("-", B7)), DATEVALUE(B7), DATE(RIGHT(B7,4), LEFT(B7, FIND("/", B7)-1), MID(B7, FIND("/", B7)+1, FIND("/", B7, FIND("/", B7)+1) - FIND("/", B7) - 1))) -> 46281 | H7: {=D7*_xlfn.XLOOKUP(C7,Clean_Inventry_Master!A:A,Clean_Inventry_Master!E:E,NOT FOUND,0)} -> 29.99 | I7: =DATE(YEAR(G7),MONTH(G7),1) -> 46266 | J7: =TEXT(I7,"mmm yyyy") -> Sep 2026
A8: TXN-1006 | B8: 2026-05-06 | C8: PROD-007 | D8: 7 | E8: Latin America | F8: Online | G8: =IF(ISNUMBER(SEARCH("-", B8)), DATEVALUE(B8), DATE(RIGHT(B8,4), LEFT(B8, FIND("/", B8)-1), MID(B8, FIND("/", B8)+1, FIND("/", B8, FIND("/", B8)+1) - FIND("/", B8) - 1))) -> 46148 | H8: {=D8*_xlfn.XLOOKUP(C8,Clean_Inventry_Master!A:A,Clean_Inventry_Master!E:E,NOT FOUND,0)} -> 168 | I8: =DATE(YEAR(G8),MONTH(G8),1) -> 46143 | J8: =TEXT(I8,"mmm yyyy") -> May 2026
A9: TXN-1007 | B9: 2026-05-08 | C9: PROD-030 | D9: 4 | E9: Asia-Pacific | F9: Online | G9: =IF(ISNUMBER(SEARCH("-", B9)), DATEVALUE(B9), DATE(RIGHT(B9,4), LEFT(B9, FIND("/", B9)-1), MID(B9, FIND("/", B9)+1, FIND("/", B9, FIND("/", B9)+1) - FIND("/", B9) - 1))) -> 46150 | H9: {=D9*_xlfn.XLOOKUP(C9,Clean_Inventry_Master!A:A,Clean_Inventry_Master!E:E,NOT FOUND,0)} -> 170 | I9: =DATE(YEAR(G9),MONTH(G9),1) -> 46143 | J9: =TEXT(I9,"mmm yyyy") -> May 2026
A10: TXN-1008 | B10: 2026-04-14 | C10: PROD-011 | D10: 14 | E10: Europe | F10: In-Store | G10: =IF(ISNUMBER(SEARCH("-", B10)), DATEVALUE(B10), DATE(RIGHT(B10,4), LEFT(B10, FIND("/", B10)-1), MID(B10, FIND("/", B10)+1, FIND("/", B10, FIND("/", B10)+1) - FIND("/", B10) - 1))) -> 46126 | H10: {=D10*_xlfn.XLOOKUP(C10,Clean_Inventry_Master!A:A,Clean_Inventry_Master!E:E,NOT FOUND,0)} -> 979.86 | I10: =DATE(YEAR(G10),MONTH(G10),1) -> 46113 | J10: =TEXT(I10,"mmm yyyy") -> Apr 2026
A11: TXN-1009 | B11: 2026-08-18 | C11: PROD-014 | D11: 12 | E11: North America | F11: Wholesale | G11: =IF(ISNUMBER(SEARCH("-", B11)), DATEVALUE(B11), DATE(RIGHT(B11,4), LEFT(B11, FIND("/", B11)-1), MID(B11, FIND("/", B11)+1, FIND("/", B11, FIND("/", B11)+1) - FIND("/", B11) - 1))) -> 46252 | H11: {=D11*_xlfn.XLOOKUP(C11,Clean_Inventry_Master!A:A,Clean_Inventry_Master!E:E,NOT FOUND,0)} -> 1679.88 | I11: =DATE(YEAR(G11),MONTH(G11),1) -> 46235 | J11: =TEXT(I11,"mmm yyyy") -> Aug 2026
A12: TXN-1010 | B12: 2026-09-10 | C12: PROD-007 | D12: 10 | E12: Asia-Pacific | F12: Online | G12: =IF(ISNUMBER(SEARCH("-", B12)), DATEVALUE(B12), DATE(RIGHT(B12,4), LEFT(B12, FIND("/", B12)-1), MID(B12, FIND("/", B12)+1, FIND("/", B12, FIND("/", B12)+1) - FIND("/", B12) - 1))) -> 46275 | H12: {=D12*_xlfn.XLOOKUP(C12,Clean_Inventry_Master!A:A,Clean_Inventry_Master!E:E,NOT FOUND,0)} -> 240 | I12: =DATE(YEAR(G12),MONTH(G12),1) -> 46266 | J12: =TEXT(I12,"mmm yyyy") -> Sep 2026
A13: TXN-1011 | B13: 2026-02-05 | C13: PROD-014 | D13: 4 | E13: Europe | F13: Wholesale | G13: =IF(ISNUMBER(SEARCH("-", B13)), DATEVALUE(B13), DATE(RIGHT(B13,4), LEFT(B13, FIND("/", B13)-1), MID(B13, FIND("/", B13)+1, FIND("/", B13, FIND("/", B13)+1) - FIND("/", B13) - 1))) -> 46058 | H13: {=D13*_xlfn.XLOOKUP(C13,Clean_Inventry_Master!A:A,Clean_Inventry_Master!E:E,NOT FOUND,0)} -> 559.96 | I13: =DATE(YEAR(G13),MONTH(G13),1) -> 46054 | J13: =TEXT(I13,"mmm yyyy") -> Feb 2026
... A851: TXN-1849 | B851: 2026-06-05 | C851: PROD-019 | D851: 13 | E851: Europe | F851: In-Store | G851: =IF(ISNUMBER(SEARCH("-", B851)), DATEVALUE(B851), DATE(RIGHT(B851,4), LEFT(B851, FIND("/", B851)-1), MID(B851, FIND("/", B851)+1, FIND("/", B851, FIND("/", B851)+1) - FIND("/", B851) - 1))) -> 46178 | H851: {=D851*_xlfn.XLOOKUP(C851,Clean_Inventry_Master!A:A,Clean_Inventry_Master!E:E,NOT FOUND,0)} -> 519.87 | I851: =DATE(YEAR(G851),MONTH(G851),1) -> 46174 | J851: =TEXT(I851,"mmm yyyy") -> Jun 2026
D853: =SUM(D:D) -> 6370 | H853: =SUM(H:H) -> 572611.45

Sheet Clean_Inventry_Master
A1: Product ID | B1: Product Name | C1: Category | D1: Unit Cost | E1: Selling Price | F1: Safety Stock Level | G1: Starting Stock | H1: Total Unit Sold | I1: Ending Inventroy | J1: Gross Revenue | K1: Inventry Status | L1: Profit
A2: PROD-001 | B2: Apex Wireless Mouse | C2: Electronics | D2: 15 | E2: 45 | F2: 150 | G2: 600 | H2: =SUMIFS(Clean_Sales_Data!D:D,Clean_Sales_Data!C:C,Clean_Inventry_Master!A2) -> 136 | I2: =G2-H2 -> 464 | J2: =H2*E2 -> 6120 | K2: {=_xlfn.IFS(I2<0,"STOCK CRISIS",I2<=F2,"REORDER",I2>F2,"STABLE")} -> STABLE | L2: =J2-(H2*D2) -> 4080
A3: PROD-003 | B3: Ultrawide 34In Monitor | C3: Electronics | D3: 210 | E3: 499 | F3: 25 | G3: 80 | H3: =SUMIFS(Clean_Sales_Data!D:D,Clean_Sales_Data!C:C,Clean_Inventry_Master!A3) -> 189 | I3: =G3-H3 -> -109 | J3: =H3*E3 -> 94311 | K3: {=_xlfn.IFS(I3<0,"STOCK CRISIS",I3<=F3,"REORDER",I3>F3,"STABLE")} -> STOCK CRISIS | L3: =J3-(H3*D3) -> 54621
A4: PROD-005 | B4: Mechanical Keyboard | C4: Electronics | D4: 40 | E4: 95 | F4: 60 | G4: 200 | H4: =SUMIFS(Clean_Sales_Data!D:D,Clean_Sales_Data!C:C,Clean_Inventry_Master!A4) -> 199 | I4: =G4-H4 -> 1 | J4: =H4*E4 -> 18905 | K4: {=_xlfn.IFS(I4<0,"STOCK CRISIS",I4<=F4,"REORDER",I4>F4,"STABLE")} -> REORDER | L4: =J4-(H4*D4) -> 10945
A5: PROD-006 | B5: Aluminum Laptop Stand | C5: Electronics | D5: 12 | E5: 35 | F5: 75 | G5: 250 | H5: =SUMIFS(Clean_Sales_Data!D:D,Clean_Sales_Data!C:C,Clean_Inventry_Master!A5) -> 175 | I5: =G5-H5 -> 75 | J5: =H5*E5 -> 6125 | K5: {=_xlfn.IFS(I5<0,"STOCK CRISIS",I5<=F5,"REORDER",I5>F5,"STABLE")} -> REORDER | L5: =J5-(H5*D5) -> 4025
A6: PROD-009 | B6: Noise Cancelling Headphones | C6: Electronics | D6: 85 | E6: 229 | F6: 30 | G6: 95 | H6: =SUMIFS(Clean_Sales_Data!D:D,Clean_Sales_Data!C:C,Clean_Inventry_Master!A6) -> 261 | I6: =G6-H6 -> -166 | J6: =H6*E6 -> 59769 | K6: {=_xlfn.IFS(I6<0,"STOCK CRISIS",I6<=F6,"REORDER",I6>F6,"STABLE")} -> STOCK CRISIS | L6: =J6-(H6*D6) -> 37584
A7: PROD-011 | B7: Hd Webcam 1080P | C7: Electronics | D7: 25 | E7: 69.99 | F7: 50 | G7: 180 | H7: =SUMIFS(Clean_Sales_Data!D:D,Clean_Sales_Data!C:C,Clean_Inventry_Master!A7) -> 175 | I7: =G7-H7 -> 5 | J7: =H7*E7 -> 12248.25 | K7: {=_xlfn.IFS(I7<0,"STOCK CRISIS",I7<=F7,"REORDER",I7>F7,"STABLE")} -> REORDER | L7: =J7-(H7*D7) -> 7873.25
A8: PROD-012 | B8: Bluetooth Speaker | C8: Electronics | D8: 30 | E8: 79.99 | F8: 40 | G8: 150 | H8: =SUMIFS(Clean_Sales_Data!D:D,Clean_Sales_Data!C:C,Clean_Inventry_Master!A8) -> 225 | I8: =G8-H8 -> -75 | J8: =H8*E8 -> 17997.75 | K8: {=_xlfn.IFS(I8<0,"STOCK CRISIS",I8<=F8,"REORDER",I8>F8,"STABLE")} -> STOCK CRISIS | L8: =J8-(H8*D8) -> 11247.75
A9: PROD-013 | B9: Dual-Band Wi-Fi Router | C9: Electronics | D9: 45 | E9: 119.99 | F9: 35 | G9: 110 | H9: =SUMIFS(Clean_Sales_Data!D:D,Clean_Sales_Data!C:C,Clean_Inventry_Master!A9) -> 194 | I9: =G9-H9 -> -84 | J9: =H9*E9 -> 23278.06 | K9: {=_xlfn.IFS(I9<0,"STOCK CRISIS",I9<=F9,"REORDER",I9>F9,"STABLE")} -> STOCK CRISIS | L9: =J9-(H9*D9) -> 14548.06
A10: PROD-014 | B10: External Ssd 1Tb | C10: Electronics | D10: 55 | E10: 139.99 | F10: 45 | G10: 160 | H10: =SUMIFS(Clean_Sales_Data!D:D,Clean_Sales_Data!C:C,Clean_Inventry_Master!A10) -> 246 | I10: =G10-H10 -> -86 | J10: =H10*E10 -> 34437.54 | K10: {=_xlfn.IFS(I10<0,"STOCK CRISIS",I10<=F10,"REORDER",I10>F10,"STABLE")} -> STOCK CRISIS | L10: =J10-(H10*D10) -> 20907.54
A11: PROD-015 | B11: Usb-C Docking Station | C11: Electronics | D11: 35 | E11: 89.99 | F11: 40 | G11: 130 | H11: =SUMIFS(Clean_Sales_Data!D:D,Clean_Sales_Data!C:C,Clean_Inventry_Master!A11) -> 231 | I11: =G11-H11 -> -101 | J11: =H11*E11 -> 20787.69 | K11: {=_xlfn.IFS(I11<0,"STOCK CRISIS",I11<=F11,"REORDER",I11>F11,"STABLE")} -> STOCK CRISIS | L11: =J11-(H11*D11) -> 12702.69
A12: PROD-002 | B12: Ergonomic Office Chair | C12: Office Supplies | D12: 65 | E12: 180 | F12: 40 | G12: 120 | H12: =SUMIFS(Clean_Sales_Data!D:D,Clean_Sales_Data!C:C,Clean_Inventry_Master!A12) -> 312 | I12: =G12-H12 -> -192 | J12: =H12*E12 -> 56160 | K12: {=_xlfn.IFS(I12<0,"STOCK CRISIS",I12<=F12,"REORDER",I12>F12,"STABLE")} -> STOCK CRISIS | L12: =J12-(H12*D12) -> 35880
A13: PROD-004 | B13: Premium Leather Journal | C13: Office Supplies | D13: 4.5 | E13: 15 | F13: 100 | G13: 400 | H13: =SUMIFS(Clean_Sales_Data!D:D,Clean_Sales_Data!C:C,Clean_Inventry_Master!A13) -> 193 | I13: =G13-H13 -> 207 | J13: =H13*E13 -> 2895 | K13: {=_xlfn.IFS(I13<0,"STOCK CRISIS",I13<=F13,"REORDER",I13>F13,"STABLE")} -> STABLE | L13: =J13-(H13*D13) -> 2026.5
... A31: PROD-030 | B31: Privacy Screen Filter 24In | C31: Home Office | D31: 16 | E31: 42.5 | F31: 30 | G31: 100 | H31: =SUMIFS(Clean_Sales_Data!D:D,Clean_Sales_Data!C:C,Clean_Inventry_Master!A31) -> 153 | I31: =G31-H31 -> -53 | J31: =H31*E31 -> 6502.5 | K31: {=_xlfn.IFS(I31<0,"STOCK CRISIS",I31<=F31,"REORDER",I31>F31,"STABLE")} -> STOCK CRISIS | L31: =J31-(H31*D31) -> 4054.5
K33: =COUNTIF(K2:K31,"STOCK CRISIS") -> 19 | L33: =SUM(L2:L31) -> 354752.45
K35: =COUNTIF(K2:K31,"REORDER") -> 4

Sheet Raw_Inventory_Master
A1: Product ID | B1: Product Name | C1: Category | D1: Unit Cost | E1: Selling Price | F1: Safety Stock Level | G1: Starting Stock
A2: PROD-001 | B2: Apex Wireless Mouse | C2: Electronics | D2: 15 | E2: 45 | F2: 150 | G2: 600
A3: PROD-003 | B3: UltraWide 34in Monitor | C3: Electronics | D3: 210 | E3: 499 | F3: 25 | G3: 80
A4: PROD-005 | B4: Mechanical Keyboard | C4: Electronics | D4: 40 | E4: 95 | F4: 60 | G4: 200
A5: PROD-006 | B5: Aluminum Laptop Stand | C5: Electronics | D5: 12 | E5: 35 | F5: 75 | G5: 250
A6: PROD-009 | B6: Noise Cancelling Headphones | C6: Electronics | D6: 85 | E6: 229 | F6: 30 | G6: 95
A7: PROD-011 | B7: HD Webcam 1080p | C7: Electronics | D7: 25 | E7: 69.99 | F7: 50 | G7: 180
A8: PROD-012 | B8: Bluetooth Speaker | C8: Electronics | D8: 30 | E8: 79.99 | F8: 40 | G8: 150
A9: PROD-013 | B9: Dual-Band Wi-Fi Router | C9: Electronics | D9: 45 | E9: 119.99 | F9: 35 | G9: 110
A10: PROD-014 | B10: External SSD 1TB | C10: Electronics | D10: 55 | E10: 139.99 | F10: 45 | G10: 160
A11: PROD-015 | B11: USB-C Docking Station | C11: Electronics | D11: 35 | E11: 89.99 | F11: 40 | G11: 130
A12: PROD-002 | B12: Ergonomic Office Chair | C12: Office Supplies | D12: 65 | E12: 180 | F12: 40 | G12: 120
A13: PROD-004 | B13: Premium Leather Journal | C13: Office Supplies | D13: 4.5 | E13: 15 | F13: 100 | G13: 400
... A31: PROD-030 | B31: Privacy Screen Filter 24in | C31: Home Office | D31: 16 | E31: 42.5 | F31: 30 | G31: 100

Sheet Raw_Sales_Data
A1: Transaction ID | B1: Date | C1: Product ID | D1: Quantity Sold | E1: Region | F1: Sales Channel
A2: TXN-1000 | B2: 2026-04-13 | C2: PROD-027 | D2: 14 | E2: Asia-Pacific | F2: Wholesale
A3: TXN-1001 | B3: 2026-09-01 | C3: prod-002 | D3: 10 | E3: Latin America | F3: In-Store
A4: TXN-1002 | B4: 07/21/2026 | C4: PROD-003 | D4: 5 | E4: Europe | F4: Wholesale
A5: TXN-1003 | B5: 02/10/2026 | C5: PROD-002 | D5: 13 | E5: Asia-Pacific | F5: Wholesale
A6: TXN-1004 | B6: 2026-08-19 | C6: PROD-020 | D6: 4 | E6: North America | F6: Online
A7: TXN-1005 | B7: 2026-09-16 | C7: PROD-010 | D7: 1 | E7: North America | F7: Wholesale
A8: TXN-1006 | B8: 2026-05-06 | C8: PROD-007 | D8: 7 | E8: Latin America | F8: Online
A9: TXN-1007 | B9: 2026-05-08 | C9: PROD-030 | D9: 4 | E9: Asia-Pacific | F9: Online
A10: TXN-1008 | B10: 2026-04-14 | C10: PROD-011 | D10: 14 | E10: Europe | F10: In-Store
A11: TXN-1009 | B11: 2026-08-18 | C11: PROD-014 | D11: 12 | E11: North America | F11: Wholesale
A12: TXN-1010 | B12: 2026-09-10 | C12: prod-007 | D12: 10 | E12: Asia-Pacific | F12: Online
A13: TXN-1011 | B13: 2026-02-05 | C13: PROD-014 | D13: 4 | E13: Europe | F13: Wholesale
... A851: TXN-1849 | B851: 2026-06-05 | C851: PROD-019 | D851: 13 | E851: Europe | F851: In-Store

Sheet chart 1
A1: Question: How many products are in each inventory status?
A3: Count of Product ID | B3: Category
A4: Inventry Status | B4: Electronics | C4: Home Office | D4: Office Supplies
A5: REORDER | B5: 3 | C5: 1
A6: STABLE | B6: 1 | C6: 3 | D6: 3
A7: STOCK CRISIS | B7: 6 | C7: 6 | D7: 7

Sheet monthly revenue
A3: Row Labels | B3: Sum of REVENUE | E3: Row Labels | F3: Sum of Quantity Sold
A4: Apr 2026 | B4: 83596.76 | E4: PROD-001 | F4: 136 | N4: Sum of Profit
A5: Aug 2026 | B5: 66818.9 | E5: PROD-002 | F5: 312 | K5: Row Labels | L5: Sum of Unit Cost | N5: 354752.45
A6: Feb 2026 | B6: 66294.77 | E6: PROD-003 | F6: 189 | K6: Adjustable Footrest | L6: 14
A7: Jan 2026 | B7: 48286.39 | E7: PROD-004 | F7: 193 | K7: Aluminum Laptop Stand | L7: 12
A8: Jul 2026 | B8: 66593.8 | E8: PROD-005 | F8: 199 | K8: Anti-Fatigue Desk Mat | L8: 11.5
A9: Jun 2026 | B9: 51588.98 | E9: PROD-006 | F9: 175 | K9: Apex Wireless Mouse | L9: 15
A10: Mar 2026 | B10: 48436.07 | E10: PROD-007 | F10: 303 | K10: Bamboo Desk Organizer | L10: 8
A11: May 2026 | B11: 53865.29 | E11: PROD-008 | F11: 253 | K11: Bluetooth Speaker | L11: 30
A12: Oct 2026 | B12: 20251.35 | E12: PROD-009 | F12: 261 | K12: Cable Management Tray | L12: 6
A13: Sep 2026 | B13: 66879.14 | E13: PROD-010 | F13: 193 | K13: Desk Scissors 3-Pack | L13: 2.5
A14: Grand Total | B14: 572611.45 | E14: PROD-011 | F14: 175 | K14: Dry Erase Whiteboard | L14: 18
E15: PROD-012 | F15: 225 | K15: Dual-Band Wi-Fi Router | L15: 45
E16: PROD-013 | F16: 194 | K16: Electric Standing Desk | L16: 140
E17: PROD-014 | F17: 246 | K17: Ergonomic Office Chair | L17: 65
E18: PROD-015 | F18: 231 | I18: Row Labels | J18: Sum of Unit Cost | K18: External Ssd 1Tb | L18: 55
E19: PROD-016 | F19: 213 | I19: Adjustable Footrest | J19: 14 | K19: File Folders Box Of 100 | L19: 6
E20: PROD-017 | F20: 172 | I20: Aluminum Laptop Stand | J20: 12 | K20: Gel Pen Multi-Pack | L20: 3
E21: PROD-018 | F21: 263 | I21: Anti-Fatigue Desk Mat | J21: 11.5 | K21: Hd Webcam 1080P | L21: 25
A22: Row Labels | B22: Sum of Profit | E22: PROD-019 | F22: 220 | I22: Apex Wireless Mouse | J22: 15 | K22: Heavy Duty Stapler | L22: 7.5
A23: Electronics | B23: 178534.29 | E23: PROD-020 | F23: 277 | I23: Bamboo Desk Organizer | J23: 8 | K23: Led Desk Lamp W/ Charger | L23: 18
A24: Home Office | B24: 92428.24 | E24: PROD-021 | F24: 157 | I24: Bluetooth Speaker | J24: 30 | K24: Lumbar Support Pillow | L24: 9.5
A25: Office Supplies | B25: 83789.92 | E25: PROD-022 | F25: 255 | I25: Cable Management Tray | J25: 6 | K25: Mechanical Keyboard | L25: 40
A26: Grand Total | B26: 354752.45 | E26: PROD-023 | F26: 206 | I26: Desk Scissors 3-Pack | J26: 2.5 | K26: Monitor Arm Mount | L26: 22
E27: PROD-024 | F27: 102 | I27: Dry Erase Whiteboard | J27: 18 | K27: Noise Cancelling Headphones | L27: 85
E28: PROD-025 | F28: 127 | I28: Dual-Band Wi-Fi Router | J28: 45 | K28: Premium Leather Journal | L28: 4.5
E29: PROD-026 | F29: 249 | I29: Electric Standing Desk | J29: 140 | K29: Privacy Screen Filter 24In | L29: 16
E30: PROD-027 | F30: 95 | I30: Ergonomic Office Chair | J30: 65 | K30: Ring Light For Video Calls | L30: 13
E31: PROD-028 | F31: 281 | I31: External Ssd 1Tb | J31: 55 | K31: Shredder High-Security | L31: 45
E32: PROD-029 | F32: 315 | I32: File Folders Box Of 100 | J32: 6 | K32: Smart Power Strip | L32: 9
E33: PROD-030 | F33: 153 | I33: Gel Pen Multi-Pack | J33: 3 | K33: Ultrawide 34In Monitor | L33: 210
E34: Grand Total | F34: 6370 | I34: Hd Webcam 1080P | J34: 25 | K34: Under-Desk Drawer Cabinet | L34: 35
I35: Heavy Duty Stapler | J35: 7.5 | K35: Usb-C Docking Station | L35: 35
I36: Led Desk Lamp W/ Charger | J36: 18 | K36: Grand Total | L36: 1005.5
I37: Lumbar Support Pillow | J37: 9.5
I38: Mechanical Keyboard | J38: 40
I39: Monitor Arm Mount | J39: 22
I40: Noise Cancelling Headphones | J40: 85
I41: Premium Leather Journal | J41: 4.5
I42: Privacy Screen Filter 24In | J42: 16
...

Sheet sales channel revenue
A3: Row Labels | B3: Sum of REVENUE | D3: Row Labels | E3: Sum of Quantity Sold
A4: In-Store | B4: 179849.68 | D4: In-Store | E4: 2073
A5: Wholesale | B5: 192529.84 | D5: Online | E5: 2196
A6: Online | B6: 200231.93 | D6: Wholesale | E6: 2101
A7: Grand Total | B7: 572611.45 | D7: Grand Total | E7: 6370
